<?xml version="1.0" encoding="UTF-8"?>
<testng-results skipped="0" failed="1" ignored="0" total="2" passed="1">
  <reporter-output>
  </reporter-output>
  <suite name="Default suite" duration-ms="95" started-at="2023-01-29T20:01:39 IST" finished-at="2023-01-29T20:01:39 IST">
    <groups>
    </groups>
    <test name="Default test" duration-ms="95" started-at="2023-01-29T20:01:39 IST" finished-at="2023-01-29T20:01:39 IST">
      <class name="pck1.RCB">
        <test-method status="PASS" signature="beforeSuite()[pri:0, instance:pck1.RCB@cd072c]" name="beforeSuite" is-config="true" duration-ms="48" started-at="2023-01-29T20:01:39 IST" finished-at="2023-01-29T20:01:39 IST">
          <reporter-output>
          </reporter-output>
        </test-method> <!-- beforeSuite -->
        <test-method status="FAIL" signature="tc1()[pri:0, instance:pck1.RCB@cd072c]" name="tc1" duration-ms="13" started-at="2023-01-29T20:01:39 IST" finished-at="2023-01-29T20:01:39 IST">
          <exception class="java.lang.AssertionError">
            <message>
              <![CDATA[expected [42] but found [4]]]>
            </message>
            <full-stacktrace>
              <![CDATA[java.lang.AssertionError: expected [42] but found [4]
at org.testng.Assert.fail(Assert.java:99)
at org.testng.Assert.failNotEquals(Assert.java:1037)
at org.testng.Assert.assertEqualsImpl(Assert.java:140)
at org.testng.Assert.assertEquals(Assert.java:122)
at org.testng.Assert.assertEquals(Assert.java:907)
at org.testng.Assert.assertEquals(Assert.java:917)
at pck1.RCB.tc1(RCB.java:37)
at sun.reflect.NativeMethodAccessorImpl.invoke0(Native Method)
at sun.reflect.NativeMethodAccessorImpl.invoke(Unknown Source)
at sun.reflect.DelegatingMethodAccessorImpl.invoke(Unknown Source)
at java.lang.reflect.Method.invoke(Unknown Source)
at org.testng.internal.MethodInvocationHelper.invokeMethod(MethodInvocationHelper.java:133)
at org.testng.internal.TestInvoker.invokeMethod(TestInvoker.java:598)
at org.testng.internal.TestInvoker.invokeTestMethod(TestInvoker.java:173)
at org.testng.internal.MethodRunner.runInSequence(MethodRunner.java:46)
at org.testng.internal.TestInvoker$MethodInvocationAgent.invoke(TestInvoker.java:824)
at org.testng.internal.TestInvoker.invokeTestMethods(TestInvoker.java:146)
at org.testng.internal.TestMethodWorker.invokeTestMethods(TestMethodWorker.java:146)
at org.testng.internal.TestMethodWorker.run(TestMethodWorker.java:128)
at java.util.ArrayList.forEach(Unknown Source)
at org.testng.TestRunner.privateRun(TestRunner.java:794)
at org.testng.TestRunner.run(TestRunner.java:596)
at org.testng.SuiteRunner.runTest(SuiteRunner.java:377)
at org.testng.SuiteRunner.runSequentially(SuiteRunner.java:371)
at org.testng.SuiteRunner.privateRun(SuiteRunner.java:332)
at org.testng.SuiteRunner.run(SuiteRunner.java:276)
at org.testng.SuiteRunnerWorker.runSuite(SuiteRunnerWorker.java:53)
at org.testng.SuiteRunnerWorker.run(SuiteRunnerWorker.java:96)
at org.testng.TestNG.runSuitesSequentially(TestNG.java:1212)
at org.testng.TestNG.runSuitesLocally(TestNG.java:1134)
at org.testng.TestNG.runSuites(TestNG.java:1063)
at org.testng.TestNG.run(TestNG.java:1031)
at org.testng.remote.AbstractRemoteTestNG.run(AbstractRemoteTestNG.java:115)
at org.testng.remote.RemoteTestNG.initAndRun(RemoteTestNG.java:251)
at org.testng.remote.RemoteTestNG.main(RemoteTestNG.java:77)
]]>
            </full-stacktrace>
          </exception> <!-- java.lang.AssertionError -->
          <reporter-output>
          </reporter-output>
        </test-method> <!-- tc1 -->
        <test-method status="PASS" signature="tc2()[pri:0, instance:pck1.RCB@cd072c]" name="tc2" duration-ms="2" started-at="2023-01-29T20:01:39 IST" finished-at="2023-01-29T20:01:39 IST">
          <reporter-output>
          </reporter-output>
        </test-method> <!-- tc2 -->
      </class> <!-- pck1.RCB -->
    </test> <!-- Default test -->
  </suite> <!-- Default suite -->
</testng-results>
